<?xml version="1.0" encoding="UTF-8"?>
<testng-results ignored="0" total="2" passed="0" failed="2" skipped="0">
  <reporter-output>
  </reporter-output>
  <suite started-at="2025-08-08T10:13:41 IST" name="Suite" finished-at="2025-08-08T10:13:57 IST" duration-ms="15905">
    <groups>
      <group name="ErrorHandling">
        <method signature="ErrorHandling.LoginErrorValidation()[pri:0, instance:org.zasya.AutoPractice.ErrorHandling@642a7222]" name="LoginErrorValidation" class="org.zasya.AutoPractice.ErrorHandling"/>
      </group> <!-- ErrorHandling -->
    </groups>
    <test started-at="2025-08-08T10:13:41 IST" name="Error Validation Test" finished-at="2025-08-08T10:13:57 IST" duration-ms="15905">
      <class name="org.zasya.AutoPractice.ErrorHandling">
        <test-method is-config="true" signature="launchApplication()[pri:0, instance:org.zasya.AutoPractice.ErrorHandling@642a7222]" started-at="2025-08-08T10:13:41 IST" name="launchApplication" finished-at="2025-08-08T10:13:45 IST" duration-ms="3781" status="PASS">
          <reporter-output>
          </reporter-output>
        </test-method> <!-- launchApplication -->
        <test-method signature="LoginErrorValidation()[pri:0, instance:org.zasya.AutoPractice.ErrorHandling@642a7222]" started-at="2025-08-08T10:13:45 IST" name="LoginErrorValidation" finished-at="2025-08-08T10:13:45 IST" duration-ms="585" status="FAIL">
          <exception class="java.lang.AssertionError">
            <message>
              <![CDATA[expected [Incorrect email or password.] but found [Incorrect email or passwor]]]>
            </message>
            <full-stacktrace>
              <![CDATA[java.lang.AssertionError: expected [Incorrect email or password.] but found [Incorrect email or passwor]
at org.testng.Assert.fail(Assert.java:111)
at org.testng.Assert.failNotEquals(Assert.java:1590)
at org.testng.Assert.assertEqualsImpl(Assert.java:150)
at org.testng.Assert.assertEquals(Assert.java:132)
at org.testng.Assert.assertEquals(Assert.java:656)
at org.testng.Assert.assertEquals(Assert.java:666)
at org.zasya.AutoPractice.ErrorHandling.LoginErrorValidation(ErrorHandling.java:20)
at java.base/jdk.internal.reflect.DirectMethodHandleAccessor.invoke(DirectMethodHandleAccessor.java:103)
at java.base/java.lang.reflect.Method.invoke(Method.java:580)
at org.testng.internal.invokers.MethodInvocationHelper.invokeMethod(MethodInvocationHelper.java:141)
at org.testng.internal.invokers.TestInvoker.invokeMethod(TestInvoker.java:687)
at org.testng.internal.invokers.TestInvoker.invokeTestMethod(TestInvoker.java:230)
at org.testng.internal.invokers.MethodRunner.runInSequence(MethodRunner.java:63)
at org.testng.internal.invokers.TestInvoker$MethodInvocationAgent.invoke(TestInvoker.java:995)
at org.testng.internal.invokers.TestInvoker.invokeTestMethods(TestInvoker.java:203)
at org.testng.internal.invokers.TestMethodWorker.invokeTestMethods(TestMethodWorker.java:154)
at org.testng.internal.invokers.TestMethodWorker.run(TestMethodWorker.java:134)
at java.base/java.util.ArrayList.forEach(ArrayList.java:1596)
at org.testng.TestRunner.privateRun(TestRunner.java:741)
at org.testng.TestRunner.run(TestRunner.java:616)
at org.testng.SuiteRunner.runTest(SuiteRunner.java:421)
at org.testng.SuiteRunner$SuiteWorker.run(SuiteRunner.java:463)
at org.testng.internal.thread.ThreadUtil.lambda$execute$0(ThreadUtil.java:64)
at java.base/java.util.concurrent.FutureTask.run(FutureTask.java:317)
at java.base/java.util.concurrent.ThreadPoolExecutor.runWorker(ThreadPoolExecutor.java:1144)
at java.base/java.util.concurrent.ThreadPoolExecutor$Worker.run(ThreadPoolExecutor.java:642)
at java.base/java.lang.Thread.run(Thread.java:1583)
]]>
            </full-stacktrace>
          </exception> <!-- java.lang.AssertionError -->
          <reporter-output>
          </reporter-output>
        </test-method> <!-- LoginErrorValidation -->
        <test-method is-config="true" signature="close()[pri:0, instance:org.zasya.AutoPractice.ErrorHandling@642a7222]" started-at="2025-08-08T10:13:46 IST" name="close" finished-at="2025-08-08T10:13:46 IST" duration-ms="90" status="PASS">
          <reporter-output>
          </reporter-output>
        </test-method> <!-- close -->
        <test-method is-config="true" signature="launchApplication()[pri:0, instance:org.zasya.AutoPractice.ErrorHandling@642a7222]" started-at="2025-08-08T10:13:46 IST" name="launchApplication" finished-at="2025-08-08T10:13:48 IST" duration-ms="2546" status="PASS">
          <reporter-output>
          </reporter-output>
        </test-method> <!-- launchApplication -->
        <test-method signature="ProductErrorValidation()[pri:0, instance:org.zasya.AutoPractice.ErrorHandling@642a7222]" started-at="2025-08-08T10:13:48 IST" name="ProductErrorValidation" finished-at="2025-08-08T10:13:57 IST" duration-ms="8285" status="FAIL">
          <exception class="java.lang.AssertionError">
            <message>
              <![CDATA[❌ Product 'IPHONE 13 PRO' not found in Cart Page expected [true] but found [false]]]>
            </message>
            <full-stacktrace>
              <![CDATA[java.lang.AssertionError: ❌ Product 'IPHONE 13 PRO' not found in Cart Page expected [true] but found [false]
at org.testng.Assert.fail(Assert.java:111)
at org.testng.Assert.failNotEquals(Assert.java:1590)
at org.testng.Assert.assertTrue(Assert.java:57)
at org.zasya.AutoPractice.ErrorHandling.ProductErrorValidation(ErrorHandling.java:40)
at java.base/jdk.internal.reflect.DirectMethodHandleAccessor.invoke(DirectMethodHandleAccessor.java:103)
at java.base/java.lang.reflect.Method.invoke(Method.java:580)
at org.testng.internal.invokers.MethodInvocationHelper.invokeMethod(MethodInvocationHelper.java:141)
at org.testng.internal.invokers.TestInvoker.invokeMethod(TestInvoker.java:687)
at org.testng.internal.invokers.TestInvoker.invokeTestMethod(TestInvoker.java:230)
at org.testng.internal.invokers.MethodRunner.runInSequence(MethodRunner.java:63)
at org.testng.internal.invokers.TestInvoker$MethodInvocationAgent.invoke(TestInvoker.java:995)
at org.testng.internal.invokers.TestInvoker.invokeTestMethods(TestInvoker.java:203)
at org.testng.internal.invokers.TestMethodWorker.invokeTestMethods(TestMethodWorker.java:154)
at org.testng.internal.invokers.TestMethodWorker.run(TestMethodWorker.java:134)
at java.base/java.util.ArrayList.forEach(ArrayList.java:1596)
at org.testng.TestRunner.privateRun(TestRunner.java:741)
at org.testng.TestRunner.run(TestRunner.java:616)
at org.testng.SuiteRunner.runTest(SuiteRunner.java:421)
at org.testng.SuiteRunner$SuiteWorker.run(SuiteRunner.java:463)
at org.testng.internal.thread.ThreadUtil.lambda$execute$0(ThreadUtil.java:64)
at java.base/java.util.concurrent.FutureTask.run(FutureTask.java:317)
at java.base/java.util.concurrent.ThreadPoolExecutor.runWorker(ThreadPoolExecutor.java:1144)
at java.base/java.util.concurrent.ThreadPoolExecutor$Worker.run(ThreadPoolExecutor.java:642)
at java.base/java.lang.Thread.run(Thread.java:1583)
]]>
            </full-stacktrace>
          </exception> <!-- java.lang.AssertionError -->
          <reporter-output>
          </reporter-output>
        </test-method> <!-- ProductErrorValidation -->
        <test-method is-config="true" signature="close()[pri:0, instance:org.zasya.AutoPractice.ErrorHandling@642a7222]" started-at="2025-08-08T10:13:57 IST" name="close" finished-at="2025-08-08T10:13:57 IST" duration-ms="109" status="PASS">
          <reporter-output>
          </reporter-output>
        </test-method> <!-- close -->
      </class> <!-- org.zasya.AutoPractice.ErrorHandling -->
    </test> <!-- Error Validation Test -->
  </suite> <!-- Suite -->
</testng-results>
